2020-12-31 18:50:26,108 INFO    MainThread:32491 [wandb_setup.py:_flush():70] setting env: {}
2020-12-31 18:50:26,108 INFO    MainThread:32491 [wandb_setup.py:_flush():70] multiprocessing start_methods=fork,spawn,forkserver
2020-12-31 18:50:26,109 INFO    MainThread:32491 [wandb_setup.py:_flush():70] setting login settings: {}
2020-12-31 18:50:26,109 INFO    MainThread:32491 [wandb_init.py:_log_setup():303] Logging user logs to /home/fkubota/Git/sand-pit/024_wandb_first/wandb/run-20201231_185026-3byfu6dy/logs/debug.log
2020-12-31 18:50:26,109 INFO    MainThread:32491 [wandb_init.py:_log_setup():304] Logging internal logs to /home/fkubota/Git/sand-pit/024_wandb_first/wandb/run-20201231_185026-3byfu6dy/logs/debug-internal.log
2020-12-31 18:50:43,977 WARNING MainThread:32491 [wandb_init.py:init():595] interrupted
Traceback (most recent call last):
  File "/home/fkubota/venv/ml/lib/python3.6/site-packages/wandb/sdk/wandb_init.py", line 575, in init
    run = wi.init()
  File "/home/fkubota/venv/ml/lib/python3.6/site-packages/wandb/sdk/wandb_init.py", line 411, in init
    ret = backend.interface.communicate_run(run, timeout=30)
  File "/home/fkubota/venv/ml/lib/python3.6/site-packages/wandb/sdk/interface/interface.py", line 542, in communicate_run
    return self._communicate_run(run, timeout=timeout)
  File "/home/fkubota/venv/ml/lib/python3.6/site-packages/wandb/sdk/interface/interface.py", line 533, in _communicate_run
    resp = self._communicate(req, timeout=timeout)
  File "/home/fkubota/venv/ml/lib/python3.6/site-packages/wandb/sdk/interface/interface.py", line 447, in _communicate
    return future.get(timeout)
  File "/home/fkubota/venv/ml/lib/python3.6/site-packages/wandb/sdk/interface/interface.py", line 63, in get
    is_set = self._object_ready.wait(timeout)
  File "/usr/lib/python3.6/threading.py", line 551, in wait
    signaled = self._cond.wait(timeout)
  File "/usr/lib/python3.6/threading.py", line 299, in wait
    gotit = waiter.acquire(True, timeout)
KeyboardInterrupt
2020-12-31 18:50:43,989 INFO    MainThread:32491 [internal.py:handle_exit():138] Internal process exited
